Workbook

Sheet Summary
B2: NAIRA FLORE
B3: Live range, pre-order capsule and Type Audit · market-pull rating · 22 Sep 2026
B4: 147 Every Naira Flore piece scored on commercial market-pull in the Indian demi-fine band (GIVA, Palmonas, Shaya, Misho tier): 55 live SKUs, the 7-piece pre-order capsule and the 85-row Type Audit range. Pure sellability lens; brand fit, IP proximity and price-band concerns are flags, never a deduction. Each row also carries a photo score out of 10 in the Material column.
B6: RATING FRAMEWORK
B7: 9–10 | C7: Hero | D7: Must-stock. Top-trend motif, broad pull, gift + self-buy.
B8: 7–8 | C8: Strong | D8: Core range. Reliable seller, sound margins, on-trend.
B9: 5–6 | C9: Viable | D9: Secondary / filler. Pretty but mid demand or narrower buyer.
B10: 4 | C10: Weak | D10: Skip unless filling a gap. Young, niche, or fading.
B11: 1–3 | C11: Exclude | D11: Off-brand. Novelty, costume, hard-seasonal, or IP risk.
B13: TIER DISTRIBUTION | C13: Count | D13: % of 147
B14: Hero (9–10) | C14: =COUNTIF(Ratings!F:F,">=9") | D14: =C14/$C$19
B15: Strong (7–8) | C15: =COUNTIFS(Ratings!F:F,">=7",Ratings!F:F,"<9") | D15: =C15/$C$19
B16: Viable (5–6) | C16: =COUNTIFS(Ratings!F:F,">=5",Ratings!F:F,"<7") | D16: =C16/$C$19
B17: Weak (4) | C17: =COUNTIF(Ratings!F:F,4) | D17: =C17/$C$19
B18: Exclude (1–3) | C18: =COUNTIFS(Ratings!F:F,">=1",Ratings!F:F,"<4") | D18: =C18/$C$19
B19: Total | C19: =SUM(C14:C18) | D19: =C19/$C$19
B21: CATEGORY STRENGTH | C21: SKUs | D21: Avg | E21: Read
B22: Earrings | C22: =COUNTIF(Ratings!E:E,"Earrings") | D22: =IF(COUNTIF(Ratings!E:E,"Earrings")=0,"",ROUND(AVERAGEIF(Ratings!E:E,"Earrings",Ratings!F:F),1)) | E22: Hoops, huggies, halo and pearl studs, bows; the deepest pool in both ranges.
B23: Ring | C23: =COUNTIF(Ratings!E:E,"Ring") | D23: =IF(COUNTIF(Ratings!E:E,"Ring")=0,"",ROUND(AVERAGEIF(Ratings!E:E,"Ring",Ratings!F:F),1)) | E23: Halo solitaires, stack bands, bold domes; colourway twins split demand.
B24: Necklace | C24: =COUNTIF(Ratings!E:E,"Necklace") | D24: =IF(COUNTIF(Ratings!E:E,"Necklace")=0,"",ROUND(AVERAGEIF(Ratings!E:E,"Necklace",Ratings!F:F),1)) | E24: Paperclip, tennis, pearl station, clover; seven of fourteen live are out of stock.
B25: Bracelet | C25: =COUNTIF(Ratings!E:E,"Bracelet") | D25: =IF(COUNTIF(Ratings!E:E,"Bracelet")=0,"",ROUND(AVERAGEIF(Ratings!E:E,"Bracelet",Ratings!F:F),1)) | E25: Tennis, paperclip, baroque pearl; seven of twelve live are out of stock.
B26: Bangle | C26: =COUNTIF(Ratings!E:E,"Bangle") | D26: =IF(COUNTIF(Ratings!E:E,"Bangle")=0,"",ROUND(AVERAGEIF(Ratings!E:E,"Bangle",Ratings!F:F),1)) | E26: Only in the audit range; marquise tennis and watch-link bangles are the strongest.
B27: Set | C27: =COUNTIF(Ratings!E:E,"Set") | D27: =IF(COUNTIF(Ratings!E:E,"Set")=0,"",ROUND(AVERAGEIF(Ratings!E:E,"Set",Ratings!F:F),1)) | E27: One live set; gift sets convert on gifting even at lower velocity.
B29: WHAT GETS CUT (consistent exclusions)
B30: • Pastel purple and lilac colourways (nine audit rows) read young and narrow the buyer.
B31: • IP-adjacent references (Love screw band, Atlas numerals, Alhambra clover, cable cuff) sell, but carry exposure for a named atelier.
B32: • Ear cuffs are a slow format in India regardless of motif.
B33: • Silver colourway twins of gold designs consistently score one point lower; they split demand rather than add it.
B34: • Raw supplier white-ground images with annotations baked in (eight audit rows) must be reshot before listing.

Sheet Ratings
A1: # | B1: Model No. | C1: Product | D1: Material / Finish | E1: Category | F1: Rating | G1: Tier | H1: Commercial rationale | I1: Flag
A2: 1 | B2: LIVE-00 | C2: Dewdrop Bezel Necklace | D2: Live · Rs 999 · out of stock · photo 6/10 | E2: Necklace | F2: 7 | G2: =IF(F2>=9,"Hero",IF(F2>=7,"Strong",IF(F2>=5,"Viable",IF(F2=4,"Weak","Exclude")))) | H2: Bezel solitaire pendant on a fine chain is evergreen daily wear and a safe gift. Photo: Piece reads tiny against the cube; needs a closer crop.
A3: 2 | B3: LIVE-01 | C3: Pearl Legacy Necklace | D3: Live · Rs 1,799 · in stock · photo 8/10 | E3: Necklace | F3: 8 | G3: =IF(F3>=9,"Hero",IF(F3>=7,"Strong",IF(F3>=5,"Viable",IF(F3=4,"Weak","Exclude")))) | H3: Baroque pearl choker with a toggle is a live trend and pearl is a top-three motif in the band. Photo: Model shot carries it; scale and drape both read.
A4: 3 | B4: LIVE-02 | C4: Baroque Shell Bracelet | D4: Live · Rs 1,799 · in stock · photo 8/10 | E4: Bracelet | F4: 7 | G4: =IF(F4>=9,"Hero",IF(F4>=7,"Strong",IF(F4>=5,"Viable",IF(F4=4,"Weak","Exclude")))) | H4: Baroque pearl toggle bracelet; pearl pulls broadly, the toggle adds the 'considered' look. Photo: Clean plinth shot, texture of the pearls reads.
A5: 4 | B5: LIVE-03 | C5: Lumière Oval Necklace | D5: Live · Rs 1,499 · out of stock · photo 7/10 | E5: Necklace | F5: 8 | G5: =IF(F5>=9,"Hero",IF(F5>=7,"Strong",IF(F5>=5,"Viable",IF(F5=4,"Weak","Exclude")))) | H5: Tennis riviere necklace is a gifting and occasion staple with deep repeat demand. Photo: Model shot but the stones blur into a line; add a macro.
A6: 5 | B6: LIVE-04 | C6: Lumière Oval Bracelet | D6: Live · Rs 1,099 · out of stock · photo 8/10 | E6: Bracelet | F6: 8 | G6: =IF(F6>=9,"Hero",IF(F6>=7,"Strong",IF(F6>=5,"Viable",IF(F6=4,"Weak","Exclude")))) | H6: Oval-cut tennis bracelet; the single most reliable bracelet format in the band. Photo: Angle shows the cut well.
A7: 6 | B7: LIVE-05 | C7: Serpentine Whisper Chain — Silver | D7: Live · Rs 1,499 · in stock · photo 7/10 | E7: Necklace | F7: 7 | G7: =IF(F7>=9,"Hero",IF(F7>=7,"Strong",IF(F7>=5,"Viable",IF(F7=4,"Weak","Exclude")))) | H7: Snake chain with a princess solitaire; snake chain is a running trend, silver widens the buyer. Photo: Silver on cream loses contrast.
A8: 7 | B8: LIVE-06 | C8: Bold Nocturne Bracelet | D8: Live · Rs 1,599 · in stock · photo 8/10 | E8: Bracelet | F8: 8 | G8: =IF(F8>=9,"Hero",IF(F8>=7,"Strong",IF(F8>=5,"Viable",IF(F8=4,"Weak","Exclude")))) | H8: Chunky paperclip bracelet; chain and link pieces are 17 percent of Palmonas' own bestseller list. Photo: Wrist shot gives scale.
A9: 8 | B9: LIVE-07 | C9: Bold Nocturne Chain | D9: Live · Rs 1,799 · in stock · photo 8/10 | E9: Necklace | F9: 8 | G9: =IF(F9>=9,"Hero",IF(F9>=7,"Strong",IF(F9>=5,"Viable",IF(F9=4,"Weak","Exclude")))) | H9: Chunky paperclip chain; same bottomless daily-wear pool as the bracelet. Photo: Neck shot, reads well.
A10: 9 | B10: LIVE-08 | C10: Petite Pearl Chain | D10: Live · Rs 1,299 · out of stock · photo 7/10 | E10: Necklace | F10: 8 | G10: =IF(F10>=9,"Hero",IF(F10>=7,"Strong",IF(F10>=5,"Viable",IF(F10=4,"Weak","Exclude")))) | H10: Pearl station necklace; Palmonas launched one this week, the motif is live now. Photo: Dainty piece on a big cube; pearls small in frame.
A11: 10 | B11: LIVE-09 | C11: Marquise Layering Set | D11: Live · Rs 1,799 · out of stock · photo 7/10 | E11: Necklace | F11: 7 | G11: =IF(F11>=9,"Hero",IF(F11>=7,"Strong",IF(F11>=5,"Viable",IF(F11=4,"Weak","Exclude")))) | H11: Two-layer set with a marquise lariat; layered pieces are 8 percent of their bestsellers. Photo: Both layers visible, slightly busy.
A12: 11 | B12: LIVE-10 | C12: Clover Charm Necklace | D12: Live · Rs 1,299 · out of stock · photo 7/10 | E12: Necklace | F12: 9 | G12: =IF(F12>=9,"Hero",IF(F12>=7,"Strong",IF(F12>=5,"Viable",IF(F12=4,"Weak","Exclude")))) | H12: Four-leaf clover pendant is the single hottest demi-fine motif right now; entry price helps. Photo: Clover small at this crop; deserves a hero.
A13: 12 | B13: LIVE-11 | C13: Verdant Drop Earrings | D13: Live · Rs 1,459 · in stock · photo 6/10 | E13: Earrings | F13: 7 | G13: =IF(F13>=9,"Hero",IF(F13>=7,"Strong",IF(F13>=5,"Viable",IF(F13=4,"Weak","Exclude")))) | H13: Green cushion drops; emerald tone has strong festive India pull, silver setting narrows it slightly. Photo: Piece is a speck on the cube.
... A28: 27 | B28: LIVE-26 | C28: Rose Verdant Band | D28: Live · Rs 1,599 · in stock · photo 7/10 | E28: Ring | F28: 6 | G28: =IF(F28>=9,"Hero",IF(F28>=7,"Strong",IF(F28>=5,"Viable",IF(F28=4,"Weak","Exclude")))) | H28: Rose-gold multi-row with green stones; busy, and rose plus green is a harder colour story in this band. Photo: Fine.
A29: 28 | B29: LIVE-27 | C29: Blush Cluster Ring | D29: Live · Rs 1,499 · in stock · photo 7/10 | E29: Ring | F29: 5 | G29: =IF(F29>=9,"Hero",IF(F29>=7,"Strong",IF(F29>=5,"Viable",IF(F29=4,"Weak","Exclude")))) | H29: Pink cluster ring; pastel pink reads young and narrows the buyer. Photo: Model shot, ring is small. | I29: pastel
A30: 29 | B30: LIVE-28 | C30: Star Point Band | D30: Live · Rs 799 · in stock · photo 8/10 | E30: Ring | F30: 5 | G30: =IF(F30>=9,"Hero",IF(F30>=7,"Strong",IF(F30>=5,"Viable",IF(F30=4,"Weak","Exclude")))) | H30: Chunky bands with tiny star and heart motifs; edges toward novelty, weak repeat purchase. Photo: Green velvet shot is one of the best in the set. | I30: novelty
A31: 30 | B31: LIVE-29 | C31: Pearl Ribbon Ring | D31: Live · Rs 1,099 · in stock · photo 8/10 | E31: Ring | F31: 9 | G31: =IF(F31>=9,"Hero",IF(F31>=7,"Strong",IF(F31>=5,"Viable",IF(F31=4,"Weak","Exclude")))) | H31: Bow with a pearl and baguette loops; bow plus pearl is the trend of the year at an entry price. Photo: Sharp; bow reads.
A32: 31 | B32: LIVE-30 | C32: Chevron Whisper Ring | D32: Live · Rs 1,299 · in stock · photo 8/10 | E32: Ring | F32: 7 | G32: =IF(F32>=9,"Hero",IF(F32>=7,"Strong",IF(F32>=5,"Viable",IF(F32=4,"Weak","Exclude")))) | H32: Double chevron pave band; stack-ring staple. Photo: Sharp.
A33: 32 | B33: LIVE-31 | C33: Cushion Halo Ring | D33: Live · Rs 1,199 · out of stock · photo 6/10 | E33: Ring | F33: 8 | G33: =IF(F33>=9,"Hero",IF(F33>=7,"Strong",IF(F33>=5,"Viable",IF(F33=4,"Weak","Exclude")))) | H33: Cushion halo solitaire in silver; evergreen, entry price. Photo: Tiny in frame on a tall cube.
A34: 33 | B34: LIVE-32 | C34: Ribbon Bead Bracelet | D34: Live · Rs 799 · in stock · photo 7/10 | E34: Bracelet | F34: 6 | G34: =IF(F34>=9,"Hero",IF(F34>=7,"Strong",IF(F34>=5,"Viable",IF(F34=4,"Weak","Exclude")))) | H34: Delicate chain bracelet with two bezels; pretty filler at Rs 799. Photo: Fine.
A35: 34 | B35: LIVE-33 | C35: Heartbead Bracelet | D35: Live · Rs 1,299 · in stock · photo 8/10 | E35: Bracelet | F35: 7 | G35: =IF(F35>=9,"Hero",IF(F35>=7,"Strong",IF(F35>=5,"Viable",IF(F35=4,"Weak","Exclude")))) | H35: Bead bracelet with a heart charm and toggle; heart is Palmonas' number one motif at 16 percent of range. Photo: Burgundy roll, reads well.
A36: 35 | B36: LIVE-34 | C36: Prism Rivière Bracelet | D36: Live · Rs 2,399 · in stock · photo 9/10 | E36: Bracelet | F36: 6 | G36: =IF(F36>=9,"Hero",IF(F36>=7,"Strong",IF(F36>=5,"Viable",IF(F36=4,"Weak","Exclude")))) | H36: Pastel multicolour baguette-halo tennis; rainbow tennis is live, but multicolour pastel narrows the buyer and Rs 2,399 is the range ceiling. Photo: The wet-burgundy hero is the best photograph in the catalogue. | I36: pastel
A37: 36 | B37: LIVE-35 | C37: Blush Station Bracelet | D37: Live · Rs 1,900 · out of stock · photo 7/10 | E37: Bracelet | F37: 5 | G37: =IF(F37>=9,"Hero",IF(F37>=7,"Strong",IF(F37>=5,"Viable",IF(F37=4,"Weak","Exclude")))) | H37: Pink bezel station bracelet; pastel pink again, and Rs 1,900 for it. Photo: Fine. | I37: pastel
A38: 37 | B38: LIVE-36 | C38: Baroque Bloom Cuff | D38: Live · Rs 1,499 · out of stock · photo 8/10 | E38: Bracelet | F38: 7 | G38: =IF(F38>=9,"Hero",IF(F38>=7,"Strong",IF(F38>=5,"Viable",IF(F38=4,"Weak","Exclude")))) | H38: Open cuff with a baroque pearl and a CZ; pearl cuff reads expensive. Photo: Green velvet, strong.
A39: 38 | B39: LIVE-37 | C39: Pearl Point Studs | D39: Live · Rs 1,499 · in stock · photo 7/10 | E39: Earrings | F39: 8 | G39: =IF(F39>=9,"Hero",IF(F39>=7,"Strong",IF(F39>=5,"Viable",IF(F39=4,"Weak","Exclude")))) | H39: Pearl in a rope-twist huggie; pearl huggie is daily-wear core. Photo: Small; the twist detail is lost.
A40: 39 | B40: LIVE-38 | C40: Trio Oval Drop Earrings | D40: Live · Rs 1,499 · in stock · photo 6/10 | E40: Earrings | F40: 7 | G40: =IF(F40>=9,"Hero",IF(F40>=7,"Strong",IF(F40>=5,"Viable",IF(F40=4,"Weak","Exclude")))) | H40: Baguette oval-link drop in two-tone; deco link, grown-up. Photo: Cropped so tight it does not read as an earring.
A41: 40 | B41: LIVE-39 | C41: Brushed Gold Huggies | D41: Live · Rs 1,099 · in stock · photo 7/10 | E41: Earrings | F41: 8 | G41: =IF(F41>=9,"Hero",IF(F41>=7,"Strong",IF(F41>=5,"Viable",IF(F41=4,"Weak","Exclude")))) | H41: Brushed chunky dome huggies; the deepest, most stable daily-wear pool. Photo: Fine; brushed finish reads.
A42: 41 | B42: LIVE-40 | C42: Pearl Drop Studs | D42: Live · Rs 1,199 · in stock · photo 8/10 | E42: Earrings | F42: 7 | G42: =IF(F42>=9,"Hero",IF(F42>=7,"Strong",IF(F42>=5,"Viable",IF(F42=4,"Weak","Exclude")))) | H42: Pearl and gold-ball drop; classic, safe gift. Photo: Ear shot, good.
A43: 42 | B43: LIVE-41 | C43: Solitaire Whisper Studs | D43: Live · Rs 1,099 · in stock · photo 8/10 | E43: Earrings | F43: 8 | G43: =IF(F43>=9,"Hero",IF(F43>=7,"Strong",IF(F43>=5,"Viable",IF(F43=4,"Weak","Exclude")))) | H43: Cushion halo studs in silver; the default gift stud. Photo: Sharp.
A44: 43 | B44: LIVE-42 | C44: Filigree Bloom Studs | D44: Live · Rs 1,499 · in stock · photo 8/10 | E44: Earrings | F44: 7 | G44: =IF(F44>=9,"Hero",IF(F44>=7,"Strong",IF(F44>=5,"Viable",IF(F44=4,"Weak","Exclude")))) | H44: Wire flower with a pearl centre; floral plus pearl, distinctive without being loud. Photo: Sharp.
A45: 44 | B45: LIVE-43 | C45: Baguette Arc Hoops | D45: Live · Rs 1,899 · in stock · photo 7/10 | E45: Earrings | F45: 8 | G45: =IF(F45>=9,"Hero",IF(F45>=7,"Strong",IF(F45>=5,"Viable",IF(F45=4,"Weak","Exclude")))) | H45: Baguette C-hoops in silver; baguette hoop is a strong everyday format. Photo: Fine.
A46: 45 | B46: LIVE-44 | C46: Textured Gold Hoops | D46: Live · Rs 1,699 · in stock · photo 7/10 | E46: Earrings | F46: 6 | G46: =IF(F46>=9,"Hero",IF(F46>=7,"Strong",IF(F46>=5,"Viable",IF(F46=4,"Weak","Exclude")))) | H46: Pave floral-cluster hoops; busy, mid demand. Photo: Fine.
A47: 46 | B47: LIVE-45 | C47: Ribbon Bow Earrings | D47: Live · Rs 1,599 · in stock · photo 8/10 | E47: Earrings | F47: 9 | G47: =IF(F47>=9,"Hero",IF(F47>=7,"Strong",IF(F47>=5,"Viable",IF(F47=4,"Weak","Exclude")))) | H47: Baguette bow studs; bow is a top-running trend and this is the clean version of it. Photo: Sharp; bow reads.
A48: 47 | B48: LIVE-46 | C48: Woven Gold Hoops | D48: Live · Rs 1,499 · in stock · photo 9/10 | E48: Earrings | F48: 8 | G48: =IF(F48>=9,"Hero",IF(F48>=7,"Strong",IF(F48>=5,"Viable",IF(F48=4,"Weak","Exclude")))) | H48: Braided chunky huggies; twisted hoops are bottomless demand. Photo: Wet-burgundy hero, excellent.
A49: 48 | B49: LIVE-47 | C49: Clover Trio Edit | D49: Live · Rs 1,999 · in stock · photo 6/10 | E49: Earrings | F49: 8 | G49: =IF(F49>=9,"Hero",IF(F49>=7,"Strong",IF(F49>=5,"Viable",IF(F49=4,"Weak","Exclude")))) | H49: Three-pair clover edit at Rs 1,999; the hottest motif, bundled. Photo: Three pairs fight for the frame; shoot the clover studs alone as the hero.
... A56: 55 | B56: LIVE-54 | C56: Rivière Eternal Necklace | D56: Live · Rs 1,799 · out of stock · photo 7/10 | E56: Necklace | F56: 8 | G56: =IF(F56>=9,"Hero",IF(F56>=7,"Strong",IF(F56>=5,"Viable",IF(F56=4,"Weak","Exclude")))) | H56: Gold tennis necklace; occasion staple. Photo: Stones blur; needs a macro.
A57: 56 | B57: CAP-zircone-solitaire | C57: The Zircone Solitaire | D57: Pre-order capsule · Rs 4,500 internal · 18k plated · photo 9/10 | E57: Ring | F57: 5 | G57: =IF(F57>=9,"Hero",IF(F57>=7,"Strong",IF(F57>=5,"Viable",IF(F57=4,"Weak","Exclude")))) | H57: A round solitaire is a nine motif, but Rs 4,500 plated sits above every demi-fine p95 and Rs 800 under Palmonas' cheapest 9kt gold lab-diamond piece; the shopper compares it to real gold. Photo: Beautiful render; reads as fine jewellery, but no skin or scale reference anywhere. | I57: price band
A58: 57 | B58: CAP-zircone-halo-studs | C58: Zircone Halo Studs | D58: Pre-order capsule · Rs 3,600 internal · 18k plated · photo 9/10 | E58: Earrings | F58: 6 | G58: =IF(F58>=9,"Hero",IF(F58>=7,"Strong",IF(F58>=5,"Viable",IF(F58=4,"Weak","Exclude")))) | H58: Halo studs are the default gift stud; Rs 3,600 is above their earring p75 of Rs 2,785 but still clearly under gold. Photo: Crisp; halo reads. | I58: price band
A59: 58 | B59: CAP-marigold-signet-ring | C59: Marigold Signet Ring | D59: Pre-order capsule · Rs 3,900 internal · 18k plated · photo 9/10 | E59: Ring | F59: 6 | G59: =IF(F59>=9,"Hero",IF(F59>=7,"Strong",IF(F59>=5,"Viable",IF(F59=4,"Weak","Exclude")))) | H59: A textured marigold with a blush stone is the most brand-defining piece in the capsule; floral sells out 49 percent at Palmonas, but Rs 3,900 is nearly double their floral median. Photo: Texture is superb; a hand shot would fix the scale question. | I59: price band
A60: 59 | B60: CAP-sage-vine-band | C60: Sage Vine Band | D60: Pre-order capsule · Rs 3,200 internal · 18k plated · photo 9/10 | E60: Ring | F60: 7 | G60: =IF(F60>=9,"Hero",IF(F60>=7,"Strong",IF(F60>=5,"Viable",IF(F60=4,"Weak","Exclude")))) | H60: Leaf and vine pieces have the highest sell-through of any motif at Palmonas at 60 percent, on only 44 SKUs; demand exceeds supply and this is the capsule's entry ring. Photo: Delicate; reads well.
...

Sheet Buy Shortlist
A1: RECOMMENDED SHORTLIST
A2: The launch buy-list: every Hero/Strong SKU (7+) grouped by what it does for the range. Pull a balanced 12–15 across daily-wear staples / trend studs / festive occasion.
A4: DAILY-WEAR STAPLES · hoops, huggies, chains, paperclip
A5: Model | B5: Product | C5: Material | D5: Rt | E5: Why it earns a slot
A6: LIVE-00 | B6: Dewdrop Bezel Necklace | C6: Live · Rs 999 · out of stock · photo 6/10 | D6: 7 | E6: Bezel solitaire pendant on a fine chain is evergreen daily wear and a safe gift. Photo: Piece reads tiny against the cube; needs a closer crop.
A7: LIVE-05 | B7: Serpentine Whisper Chain — Silver | C7: Live · Rs 1,499 · in stock · photo 7/10 | D7: 7 | E7: Snake chain with a princess solitaire; snake chain is a running trend, silver widens the buyer. Photo: Silver on cream loses contrast.
A8: LIVE-06 | B8: Bold Nocturne Bracelet | C8: Live · Rs 1,599 · in stock · photo 8/10 | D8: 8 | E8: Chunky paperclip bracelet; chain and link pieces are 17 percent of Palmonas' own bestseller list. Photo: Wrist shot gives scale.
A9: LIVE-07 | B9: Bold Nocturne Chain | C9: Live · Rs 1,799 · in stock · photo 8/10 | D9: 8 | E9: Chunky paperclip chain; same bottomless daily-wear pool as the bracelet. Photo: Neck shot, reads well.
A10: LIVE-38 | B10: Trio Oval Drop Earrings | C10: Live · Rs 1,499 · in stock · photo 6/10 | D10: 7 | E10: Baguette oval-link drop in two-tone; deco link, grown-up. Photo: Cropped so tight it does not read as an earring.
A11: LIVE-39 | B11: Brushed Gold Huggies | C11: Live · Rs 1,099 · in stock · photo 7/10 | D11: 8 | E11: Brushed chunky dome huggies; the deepest, most stable daily-wear pool. Photo: Fine; brushed finish reads.
A12: LIVE-43 | B12: Baguette Arc Hoops | C12: Live · Rs 1,899 · in stock · photo 7/10 | D12: 8 | E12: Baguette C-hoops in silver; baguette hoop is a strong everyday format. Photo: Fine.
A13: LIVE-46 | B13: Woven Gold Hoops | C13: Live · Rs 1,499 · in stock · photo 9/10 | D13: 8 | E13: Braided chunky huggies; twisted hoops are bottomless demand. Photo: Wet-burgundy hero, excellent.
A14: LIVE-48 | B14: Molten Bloom Hoops | C14: Live · Rs 1,300 · out of stock · photo 8/10 | D14: 7 | E14: Molten irregular huggies; the molten trend at an entry price. Photo: Surface reads.
A15: LIVE-50 | B15: Toggle Link Chain | C15: Live · Rs 1,499 · in stock · photo 8/10 | D15: 8 | E15: Paperclip chain with a toggle ring; daily-wear chain, worn shot sells it. Photo: Neck shot, good.
A16: LIVE-52 | B16: Serpentine Whisper Chain | C16: Live · Rs 1,849 · out of stock · photo 7/10 | D16: 7 | E16: Gold snake chain with a square solitaire; solid. Photo: Fine.
A17: LIVE-53 | B17: Heartline Paperclip Necklace | C17: Live · Rs 1,899 · in stock · photo 7/10 | D17: 7 | E17: Half paperclip, half pave hearts; hearts are their top motif, paperclip is a top format. Photo: Fine.
... A26: AUD-R77 WE20580C | B26: Rivière Huggies — Silver | C26: Type Audit · Rs 1,999 · Edition One · photo 8/10 | D26: 7 | E26: CZ hoops in silver; daily-wear staple. Photo: Plinth.
A28: TENNIS AND BAGUETTE · the occasion engine
A29: Model | B29: Product | C29: Material | D29: Rt | E29: Why it earns a slot
A30: LIVE-03 | B30: Lumière Oval Necklace | C30: Live · Rs 1,499 · out of stock · photo 7/10 | D30: 8 | E30: Tennis riviere necklace is a gifting and occasion staple with deep repeat demand. Photo: Model shot but the stones blur into a line; add a macro.
A31: LIVE-04 | B31: Lumière Oval Bracelet | C31: Live · Rs 1,099 · out of stock · photo 8/10 | D31: 8 | E31: Oval-cut tennis bracelet; the single most reliable bracelet format in the band. Photo: Angle shows the cut well.
A32: LIVE-13 | B32: Rivière of Light Bracelet | C32: Live · Rs 1,249 · out of stock · photo 7/10 | D32: 8 | E32: Round-CZ tennis bracelet; staple format, entry price. Photo: Reads as a thin line; a macro of the setting would sell it.
A33: LIVE-18 | B33: Baguette Éclat Bracelet | C33: Live · Rs 1,800 · out of stock · photo 8/10 | D33: 8 | E33: Baguette tennis bracelet; deco, grown-up, photographs well and gifts well. Photo: Burgundy roll is a strong prop.
A34: LIVE-29 | B34: Pearl Ribbon Ring | C34: Live · Rs 1,099 · in stock · photo 8/10 | D34: 9 | E34: Bow with a pearl and baguette loops; bow plus pearl is the trend of the year at an entry price. Photo: Sharp; bow reads.
A35: LIVE-45 | B35: Ribbon Bow Earrings | C35: Live · Rs 1,599 · in stock · photo 8/10 | D35: 9 | E35: Baguette bow studs; bow is a top-running trend and this is the clean version of it. Photo: Sharp; bow reads.
A36: LIVE-54 | B36: Rivière Eternal Necklace | C36: Live · Rs 1,799 · out of stock · photo 7/10 | D36: 8 | E36: Gold tennis necklace; occasion staple. Photo: Stones blur; needs a macro.
A37: AUD-R03 YF3165-NEC | B37: Baguette Rivière Choker | C37: Type Audit · Rs 2,749 · New factory · photo 8/10 | D37: 8 | E37: Baguette tennis choker; deco, occasion-ready, photographs beautifully. Photo: Plinth; stones crisp.
A38: AUD-R05 YF3165-NEC-RBY | B38: Baguette Rivière Choker — Ruby | C38: Type Audit · Rs 2,749 · New factory · photo 8/10 | D38: 7 | E38: Ruby colourway; red reads festive and bridal-adjacent, strong India pull. Photo: Model shot, the best of the row.
A39: AUD-R06 YF3165-NEC-VRD | B39: Baguette Rivière Choker — Verdant | C39: Type Audit · Rs 2,749 · New factory · photo 8/10 | D39: 8 | E39: Emerald colourway; green sells out 56 percent at Palmonas, above their average. Photo: Plinth; colour reads.
A40: AUD-R07 YF3165-BRA | B40: Baguette Rivière Bracelet | C40: Type Audit · Rs 1,899 · New factory · photo 8/10 | D40: 8 | E40: Baguette tennis bracelet; the bracelet staple in its grown-up cut. Photo: Plinth.
A41: AUD-R09 YF3165-BRA-RBY | B41: Baguette Rivière Bracelet — Ruby | C41: Type Audit · Rs 1,899 · New factory · photo 8/10 | D41: 7 | E41: Ruby bracelet; festive pull. Photo: Plinth.
... A51: AUD-R83 WR20900B | B51: Nacre Triple Wrap | C51: Type Audit · Rs 1,999 · Edition One · photo 8/10 | D51: 7 | E51: Triple band with mother-of-pearl and baguettes; MOP reads expensive and is a live neutral. Photo: Plinth.
A53: PEARL · baroque, station, huggie
A54: Model | B54: Product | C54: Material | D54: Rt | E54: Why it earns a slot
A55: LIVE-01 | B55: Pearl Legacy Necklace | C55: Live · Rs 1,799 · in stock · photo 8/10 | D55: 8 | E55: Baroque pearl choker with a toggle is a live trend and pearl is a top-three motif in the band. Photo: Model shot carries it; scale and drape both read.
A56: LIVE-02 | B56: Baroque Shell Bracelet | C56: Live · Rs 1,799 · in stock · photo 8/10 | D56: 7 | E56: Baroque pearl toggle bracelet; pearl pulls broadly, the toggle adds the 'considered' look. Photo: Clean plinth shot, texture of the pearls reads.
A57: LIVE-08 | B57: Petite Pearl Chain | C57: Live · Rs 1,299 · out of stock · photo 7/10 | D57: 8 | E57: Pearl station necklace; Palmonas launched one this week, the motif is live now. Photo: Dainty piece on a big cube; pearls small in frame.
A58: LIVE-17 | B58: Pearl Reverie Bracelet | C58: Live · Rs 899 · out of stock · photo 7/10 | D58: 7 | E58: Paperclip chain with pearls and an open circle; two live motifs at an entry price. Photo: Clean.
A59: LIVE-24 | B59: Verdant Circlet Studs | C59: Live · Rs 1,499 · in stock · photo 8/10 | D59: 8 | E59: Emerald cushion with pearl and CZ cluster; emerald plus pearl is a festive and wedding-guest winner. Photo: Colour and cluster both read.
A60: LIVE-36 | B60: Baroque Bloom Cuff | C60: Live · Rs 1,499 · out of stock · photo 8/10 | D60: 7 | E60: Open cuff with a baroque pearl and a CZ; pearl cuff reads expensive. Photo: Green velvet, strong.
...
